Workbook

Sheet Dashboard
B1: PROJECT RISK & HEALTH DASHBOARD - Proyek X PROJECT Perusahaan X (Perusahaan X)
B2: ="Reporting Period: "&Input_Bulanan!D5&" | Status: "&Input_Bulanan!F5&" | Dicetak: "&TEXT(TODAY(),"DD-MM-YYYY") -> Reporting Period: Agustus 2026 | Status: DRAFT | Dicetak: 20-07-2026
B4: PANEL A - PROJECT HEALTH OVERVIEW (Retrospective Performance) | M4: PANEL B - CURRENT RISK EXPOSURE (Prospective Threats)
B5: Overall Project Health Score (PHS) | G5: Sub-Index Readiness & Performance | M5: Overall Risk Level (Composite) | R5: Risk Profile Heat Map (Likelihood x Consequence)
B6: =((IF(Input_Bulanan!D11>=1,100,Input_Bulanan!D11*100)*0.2)+(IF(Input_Bulanan!D13>=1,100,Input_Bulanan!D13*100)*0.2)+(Input_Bulanan!D22*100*0.2)+(Input_Bulanan!D29*100*0.2)+(Input_Bulanan!D38*100*0.2))/100 -> 0.691 | G6: Supply Readiness Index (SRI) | K6: =Input_Bulanan!D22 -> 0.067 | M6: =Input_Bulanan!D45 -> Moderate | R6: L=5 | S6: =IF(AND(Input_Bulanan!$G$74=1,Input_Bulanan!$F$74=5),Input_Bulanan!$C$74,IF(AND(Input_Bulanan!$G$75=1,Input_Bulanan!$F$75=5),Input_Bulanan!$C$75,IF(AND(Input_Bulanan!$G$76=1,Input_Bulanan!$F$76=5),Input_Bulanan!$C$76,IF(AND(Input_Bulanan!$G$77=1,Input_Bulanan!$F$77=5),Input_Bulanan!$C$77,"")))) | T6: =IF(AND(Input_Bulanan!$G$74=2,Input_Bulanan!$F$74=5),Input_Bulanan!$C$74,IF(AND(Input_Bulanan!$G$75=2,Input_Bulanan!$F$75=5),Input_Bulanan!$C$75,IF(AND(Input_Bulanan!$G$76=2,Input_Bulanan!$F$76=5),Input_Bulanan!$C$76,IF(AND(Input_Bulanan!$G$77=2,Input_Bulanan!$F$77=5),Input_Bulanan!$C$77,"")))) | U6: =IF(AND(Input_Bulanan!$G$74=3,Input_Bulanan!$F$74=5),Input_Bulanan!$C$74,IF(AND(Input_Bulanan!$G$75=3,Input_Bulanan!$F$75=5),Input_Bulanan!$C$75,IF(AND(Input_Bulanan!$G$76=3,Input_Bulanan!$F$76=5),Input_Bulanan!$C$76,IF(AND(Input_Bulanan!$G$77=3,Input_Bulanan!$F$77=5),Input_Bulanan!$C$77,"")))) | V6: =IF(AND(Input_Bulanan!$G$74=4,Input_Bulanan!$F$74=5),Input_Bulanan!$C$74,IF(AND(Input_Bulanan!$G$75=4,Input_Bulanan!$F$75=5),Input_Bulanan!$C$75,IF(AND(Input_Bulanan!$G$76=4,Input_Bulanan!$F$76=5),Input_Bulanan!$C$76,IF(AND(Input_Bulanan!$G$77=4,Input_Bulanan!$F$77=5),Input_Bulanan!$C$77,"")))) | W6: =IF(AND(Input_Bulanan!$G$74=5,Input_Bulanan!$F$74=5),Input_Bulanan!$C$74,IF(AND(Input_Bulanan!$G$75=5,Input_Bulanan!$F$75=5),Input_Bulanan!$C$75,IF(AND(Input_Bulanan!$G$76=5,Input_Bulanan!$F$76=5),Input_Bulanan!$C$76,IF(AND(Input_Bulanan!$G$77=5,Input_Bulanan!$F$77=5),Input_Bulanan!$C$77,"")))) -> C2
R7: L=4 | S7: =IF(AND(Input_Bulanan!$G$74=1,Input_Bulanan!$F$74=4),Input_Bulanan!$C$74,IF(AND(Input_Bulanan!$G$75=1,Input_Bulanan!$F$75=4),Input_Bulanan!$C$75,IF(AND(Input_Bulanan!$G$76=1,Input_Bulanan!$F$76=4),Input_Bulanan!$C$76,IF(AND(Input_Bulanan!$G$77=1,Input_Bulanan!$F$77=4),Input_Bulanan!$C$77,"")))) | T7: =IF(AND(Input_Bulanan!$G$74=2,Input_Bulanan!$F$74=4),Input_Bulanan!$C$74,IF(AND(Input_Bulanan!$G$75=2,Input_Bulanan!$F$75=4),Input_Bulanan!$C$75,IF(AND(Input_Bulanan!$G$76=2,Input_Bulanan!$F$76=4),Input_Bulanan!$C$76,IF(AND(Input_Bulanan!$G$77=2,Input_Bulanan!$F$77=4),Input_Bulanan!$C$77,"")))) | U7: =IF(AND(Input_Bulanan!$G$74=3,Input_Bulanan!$F$74=4),Input_Bulanan!$C$74,IF(AND(Input_Bulanan!$G$75=3,Input_Bulanan!$F$75=4),Input_Bulanan!$C$75,IF(AND(Input_Bulanan!$G$76=3,Input_Bulanan!$F$76=4),Input_Bulanan!$C$76,IF(AND(Input_Bulanan!$G$77=3,Input_Bulanan!$F$77=4),Input_Bulanan!$C$77,"")))) | V7: =IF(AND(Input_Bulanan!$G$74=4,Input_Bulanan!$F$74=4),Input_Bulanan!$C$74,IF(AND(Input_Bulanan!$G$75=4,Input_Bulanan!$F$75=4),Input_Bulanan!$C$75,IF(AND(Input_Bulanan!$G$76=4,Input_Bulanan!$F$76=4),Input_Bulanan!$C$76,IF(AND(Input_Bulanan!$G$77=4,Input_Bulanan!$F$77=4),Input_Bulanan!$C$77,"")))) -> C3 | W7: =IF(AND(Input_Bulanan!$G$74=5,Input_Bulanan!$F$74=4),Input_Bulanan!$C$74,IF(AND(Input_Bulanan!$G$75=5,Input_Bulanan!$F$75=4),Input_Bulanan!$C$75,IF(AND(Input_Bulanan!$G$76=5,Input_Bulanan!$F$76=4),Input_Bulanan!$C$76,IF(AND(Input_Bulanan!$G$77=5,Input_Bulanan!$F$77=4),Input_Bulanan!$C$77,"")))) -> C1
G8: Project Execution Index (PEI) | K8: =Input_Bulanan!D29 -> 0.768 | R8: L=3 | S8: =IF(AND(Input_Bulanan!$G$74=1,Input_Bulanan!$F$74=3),Input_Bulanan!$C$74,IF(AND(Input_Bulanan!$G$75=1,Input_Bulanan!$F$75=3),Input_Bulanan!$C$75,IF(AND(Input_Bulanan!$G$76=1,Input_Bulanan!$F$76=3),Input_Bulanan!$C$76,IF(AND(Input_Bulanan!$G$77=1,Input_Bulanan!$F$77=3),Input_Bulanan!$C$77,"")))) | T8: =IF(AND(Input_Bulanan!$G$74=2,Input_Bulanan!$F$74=3),Input_Bulanan!$C$74,IF(AND(Input_Bulanan!$G$75=2,Input_Bulanan!$F$75=3),Input_Bulanan!$C$75,IF(AND(Input_Bulanan!$G$76=2,Input_Bulanan!$F$76=3),Input_Bulanan!$C$76,IF(AND(Input_Bulanan!$G$77=2,Input_Bulanan!$F$77=3),Input_Bulanan!$C$77,"")))) | U8: =IF(AND(Input_Bulanan!$G$74=3,Input_Bulanan!$F$74=3),Input_Bulanan!$C$74,IF(AND(Input_Bulanan!$G$75=3,Input_Bulanan!$F$75=3),Input_Bulanan!$C$75,IF(AND(Input_Bulanan!$G$76=3,Input_Bulanan!$F$76=3),Input_Bulanan!$C$76,IF(AND(Input_Bulanan!$G$77=3,Input_Bulanan!$F$77=3),Input_Bulanan!$C$77,"")))) -> C4 | V8: =IF(AND(Input_Bulanan!$G$74=4,Input_Bulanan!$F$74=3),Input_Bulanan!$C$74,IF(AND(Input_Bulanan!$G$75=4,Input_Bulanan!$F$75=3),Input_Bulanan!$C$75,IF(AND(Input_Bulanan!$G$76=4,Input_Bulanan!$F$76=3),Input_Bulanan!$C$76,IF(AND(Input_Bulanan!$G$77=4,Input_Bulanan!$F$77=3),Input_Bulanan!$C$77,"")))) | W8: =IF(AND(Input_Bulanan!$G$74=5,Input_Bulanan!$F$74=3),Input_Bulanan!$C$74,IF(AND(Input_Bulanan!$G$75=5,Input_Bulanan!$F$75=3),Input_Bulanan!$C$75,IF(AND(Input_Bulanan!$G$76=5,Input_Bulanan!$F$76=3),Input_Bulanan!$C$76,IF(AND(Input_Bulanan!$G$77=5,Input_Bulanan!$F$77=3),Input_Bulanan!$C$77,""))))
R9: L=2 | S9: =IF(AND(Input_Bulanan!$G$74=1,Input_Bulanan!$F$74=2),Input_Bulanan!$C$74,IF(AND(Input_Bulanan!$G$75=1,Input_Bulanan!$F$75=2),Input_Bulanan!$C$75,IF(AND(Input_Bulanan!$G$76=1,Input_Bulanan!$F$76=2),Input_Bulanan!$C$76,IF(AND(Input_Bulanan!$G$77=1,Input_Bulanan!$F$77=2),Input_Bulanan!$C$77,"")))) | T9: =IF(AND(Input_Bulanan!$G$74=2,Input_Bulanan!$F$74=2),Input_Bulanan!$C$74,IF(AND(Input_Bulanan!$G$75=2,Input_Bulanan!$F$75=2),Input_Bulanan!$C$75,IF(AND(Input_Bulanan!$G$76=2,Input_Bulanan!$F$76=2),Input_Bulanan!$C$76,IF(AND(Input_Bulanan!$G$77=2,Input_Bulanan!$F$77=2),Input_Bulanan!$C$77,"")))) | U9: =IF(AND(Input_Bulanan!$G$74=3,Input_Bulanan!$F$74=2),Input_Bulanan!$C$74,IF(AND(Input_Bulanan!$G$75=3,Input_Bulanan!$F$75=2),Input_Bulanan!$C$75,IF(AND(Input_Bulanan!$G$76=3,Input_Bulanan!$F$76=2),Input_Bulanan!$C$76,IF(AND(Input_Bulanan!$G$77=3,Input_Bulanan!$F$77=2),Input_Bulanan!$C$77,"")))) | V9: =IF(AND(Input_Bulanan!$G$74=4,Input_Bulanan!$F$74=2),Input_Bulanan!$C$74,IF(AND(Input_Bulanan!$G$75=4,Input_Bulanan!$F$75=2),Input_Bulanan!$C$75,IF(AND(Input_Bulanan!$G$76=4,Input_Bulanan!$F$76=2),Input_Bulanan!$C$76,IF(AND(Input_Bulanan!$G$77=4,Input_Bulanan!$F$77=2),Input_Bulanan!$C$77,"")))) | W9: =IF(AND(Input_Bulanan!$G$74=5,Input_Bulanan!$F$74=2),Input_Bulanan!$C$74,IF(AND(Input_Bulanan!$G$75=5,Input_Bulanan!$F$75=2),Input_Bulanan!$C$75,IF(AND(Input_Bulanan!$G$76=5,Input_Bulanan!$F$76=2),Input_Bulanan!$C$76,IF(AND(Input_Bulanan!$G$77=5,Input_Bulanan!$F$77=2),Input_Bulanan!$C$77,""))))
B10: =IF(B6>=0.9,"HIJAU - SEHAT",IF(B6>=0.75,"KUNING - PANTAU",IF(B6>=0.6,"ORANYE - WASPADA","MERAH - KRITIS"))) -> ORANYE - WASPADA | G10: Commercial Readiness Index (CRI) | K10: =Input_Bulanan!D38 -> 0.62 | M10: ="Skor Komposit: "&TEXT(Input_Bulanan!D44,"0,00")&" / 100" -> Skor Komposit: 45,80 / 100 | R10: L=1 | S10: =IF(AND(Input_Bulanan!$G$74=1,Input_Bulanan!$F$74=1),Input_Bulanan!$C$74,IF(AND(Input_Bulanan!$G$75=1,Input_Bulanan!$F$75=1),Input_Bulanan!$C$75,IF(AND(Input_Bulanan!$G$76=1,Input_Bulanan!$F$76=1),Input_Bulanan!$C$76,IF(AND(Input_Bulanan!$G$77=1,Input_Bulanan!$F$77=1),Input_Bulanan!$C$77,"")))) | T10: =IF(AND(Input_Bulanan!$G$74=2,Input_Bulanan!$F$74=1),Input_Bulanan!$C$74,IF(AND(Input_Bulanan!$G$75=2,Input_Bulanan!$F$75=1),Input_Bulanan!$C$75,IF(AND(Input_Bulanan!$G$76=2,Input_Bulanan!$F$76=1),Input_Bulanan!$C$76,IF(AND(Input_Bulanan!$G$77=2,Input_Bulanan!$F$77=1),Input_Bulanan!$C$77,"")))) | U10: =IF(AND(Input_Bulanan!$G$74=3,Input_Bulanan!$F$74=1),Input_Bulanan!$C$74,IF(AND(Input_Bulanan!$G$75=3,Input_Bulanan!$F$75=1),Input_Bulanan!$C$75,IF(AND(Input_Bulanan!$G$76=3,Input_Bulanan!$F$76=1),Input_Bulanan!$C$76,IF(AND(Input_Bulanan!$G$77=3,Input_Bulanan!$F$77=1),Input_Bulanan!$C$77,"")))) | V10: =IF(AND(Input_Bulanan!$G$74=4,Input_Bulanan!$F$74=1),Input_Bulanan!$C$74,IF(AND(Input_Bulanan!$G$75=4,Input_Bulanan!$F$75=1),Input_Bulanan!$C$75,IF(AND(Input_Bulanan!$G$76=4,Input_Bulanan!$F$76=1),Input_Bulanan!$C$76,IF(AND(Input_Bulanan!$G$77=4,Input_Bulanan!$F$77=1),Input_Bulanan!$C$77,"")))) | W10: =IF(AND(Input_Bulanan!$G$74=5,Input_Bulanan!$F$74=1),Input_Bulanan!$C$74,IF(AND(Input_Bulanan!$G$75=5,Input_Bulanan!$F$75=1),Input_Bulanan!$C$75,IF(AND(Input_Bulanan!$G$76=5,Input_Bulanan!$F$76=1),Input_Bulanan!$C$76,IF(AND(Input_Bulanan!$G$77=5,Input_Bulanan!$F$77=1),Input_Bulanan!$C$77,""))))
R11: C -> | S11: 1 | T11: 2 | U11: 3 | V11: 4 | W11: 5
B12: Key Financial & Schedule | G12: Master Schedule S-Curve (USD Juta) | M12: Risk Register - Risiko Aktif | R12: Legenda Top Risk (C1-C4)
B13: Cost Performance Index (CPI) | E13: =Input_Bulanan!D11 -> 1 | G13: Planned Value (PV) | J13: =Input_Bulanan!D8 -> 100 | M13: High | P13: =Input_Bulanan!D48 -> 5 | R13: =Input_Bulanan!C74 -> C1 | S13: =Input_Bulanan!D74&" | L="&Input_Bulanan!F74&", C="&Input_Bulanan!G74&", Skala="&Input_Bulanan!H74&" -> "&Input_Bulanan!I74 -> Salt Supply Disruption (gangguan pasokan garam industri) | L=4, C=5, Skala=24 -> High
B14: Schedule Performance Index (SPI) | E14: =Input_Bulanan!D13 -> 1 | G14: Earned Value (EV) | J14: =Input_Bulanan!D9 -> 100 | M14: Moderate to High | P14: =Input_Bulanan!D49 -> 11 | R14: =Input_Bulanan!C75 -> C2 | S14: =Input_Bulanan!D75&" | L="&Input_Bulanan!F75&", C="&Input_Bulanan!G75&", Skala="&Input_Bulanan!H75&" -> "&Input_Bulanan!I75 -> Commissioning Delay (keterlambatan commissioning) | L=5, C=5, Skala=25 -> High
B15: Cost Variance (CV), USD Juta | E15: =Input_Bulanan!D12 -> 0 | G15: Actual Cost (AC) | J15: =Input_Bulanan!D10 -> 100 | M15: Moderate | P15: =Input_Bulanan!D50 -> 18 | R15: =Input_Bulanan!C76 -> C3 | S15: =Input_Bulanan!D76&" | L="&Input_Bulanan!F76&", C="&Input_Bulanan!G76&", Skala="&Input_Bulanan!H76&" -> "&Input_Bulanan!I76 -> EPC Interface Issue (isu EPC interface lintas kontraktor) | L=4, C=4, Skala=19 -> Moderate to High
B16: Schedule Variance (SV), USD Juta | E16: =Input_Bulanan!D14 -> 0 | G16: (Bar proporsional: lihat conditional formatting / grafik pada versi HTML) | M16: Low to Moderate | P16: =Input_Bulanan!D51 -> 4 | R16: =Input_Bulanan!C77 -> C4 | S16: =Input_Bulanan!D77&" | L="&Input_Bulanan!F77&", C="&Input_Bulanan!G77&", Skala="&Input_Bulanan!H77&" -> "&Input_Bulanan!I77 -> Long Lead Equipment (keterlambatan peralatan utama) | L=3, C=3, Skala=13 -> Moderate
M17: Low | P17: =Input_Bulanan!D52 -> 3
M18: Total Risiko Aktif | P18: =Input_Bulanan!D53 -> 41
B20: Catatan Metodologi | M20: Mitigation Health Progress
M21: Completed Mitigations | P21: =Input_Bulanan!D56 -> 0.82
M22: On Track Mitigations | P22: =Input_Bulanan!D57 -> 0.18
M23: Overdue Actions | P23: =Input_Bulanan!D58 -> 0.76
M24: Need Escalation (jumlah aksi) | P24: =Input_Bulanan!D59 -> 5
B26: PANEL C - EARLY WARNING SYSTEM (EWS) ALERTS
B27: Parameter | G27: Threshold | K27: Aktual | M27: Aman | N27: Waspada | O27: Bahaya | P27: Implikasi Operasional & Finansial
B28: Salt Inventory (hari ketahanan) | G28: Min. 30 hari | K28: =Input_Bulanan!E63 -> 24 | M28: =IF(Input_Bulanan!H63="Aman","V","") | N28: =IF(Input_Bulanan!H63="Waspada","V","") | O28: =IF(Input_Bulanan!H63="Bahaya","V","") -> V | P28: Menimbulkan risiko penghentian mendadak kiln kalsinasi akibat keterlambatan kapal bersandar.
B29: Procurement Progress (%) | G29: Min. 80% | K29: =Input_Bulanan!E64 -> 0.73 | M29: =IF(Input_Bulanan!H64="Aman","V","") | N29: =IF(Input_Bulanan!H64="Waspada","V","") -> V | O29: =IF(Input_Bulanan!H64="Bahaya","V","") | P29: Menunda kedatangan material pemipaan di area penukar panas utama.
B30: Project SPI | G30: SPI >= 1,00 | K30: =Input_Bulanan!E65 -> 0.94 | M30: =IF(Input_Bulanan!H65="Aman","V","") | N30: =IF(Input_Bulanan!H65="Waspada","V","") -> V | O30: =IF(Input_Bulanan!H65="Bahaya","V","") | P30: Proyek terlambat 6% dari baseline rencana, mengancam target penyelesaian Maret 2028.
B31: Supplier Qualification (%) | G31: 100% terverifikasi | K31: =Input_Bulanan!E66 -> 0.75 | M31: =IF(Input_Bulanan!H66="Aman","V","") | N31: =IF(Input_Bulanan!H66="Waspada","V","") | O31: =IF(Input_Bulanan!H66="Bahaya","V","") -> V | P31: Garam domestik berisiko kadar kalsium tinggi, berpotensi menyumbat tower karbonasi.
B32: Commissioning Readiness (%) | G32: Min. 60% | K32: =Input_Bulanan!E67 -> 0.42 | M32: =IF(Input_Bulanan!H67="Aman","V","") | N32: =IF(Input_Bulanan!H67="Waspada","V","") | O32: =IF(Input_Bulanan!H67="Bahaya","V","") -> V | P32: Menunda masa uji coba fungsional alat berputar dan utilitas utama di ISBL.
B33: Product Qualification (%) | G33: Min. 50% | K33: =Input_Bulanan!E68 -> 0.4 | M33: =IF(Input_Bulanan!H68="Aman","V","") | N33: =IF(Input_Bulanan!H68="Waspada","V","") | O33: =IF(Input_Bulanan!H68="Bahaya","V","") -> V | P33: Potensi penolakan serapan pasar untuk aplikasi industri kaca lembaran (produk premium).
B35: PANEL D - EXECUTIVE ACTIONS & DECISION REQUIRED
B36: ="Prioritas 1—2: [1] " & INDEX(Risk_Action_Tracker!E$6:E$15, MATCH(LARGE(Risk_Action_Tracker!Z$6:Z$15, 1), Risk_Action_Tracker!Z$6:Z$15, 0)) & " · [2] " & INDEX(Risk_Action_Tracker!E$6:E$15, MATCH(LARGE(Risk_Action_Tracker!Z$6:Z$15, 2), Risk_Action_Tracker!Z$6:Z$15, 0)) -> Prioritas 1—2: [1] Mengesahkan pembentukan tim Interface Coordinator dan menerapkan Interface Management Plan (IMP) yang mengikat seluruh kontraktor; mengharuskan Rekind menyelaraskan jadwal penyusunan gambar detail dengan kemajuan ISBL EPC-A. · [2] Memberikan dispensasi perpanjangan jaminan pelaksanaan secara terkendali; meminta Parent Company Guarantee dari PT Perusahaan Induk X (Persero) untuk menjamin ketersediaan pendanaan bila Rekind menghadapi kendala likuiditas.
B37: Rincian lengkap: lihat sheet 'Risk_Action_Tracker' - Executive Action Tracker Direksi/PSC.

Sheet Referensi_Threshold
A2: REFERENSI FORMULA & AMBANG BATAS (THRESHOLD) — PROJECT RISK & HEALTH DASHBOARD
A3: Proyek X Project Perusahaan X | Sumber: Standarisasi Eksekutif Project Risk & Health Dashboard (Studi Kelayakan Deloitte; Risk Register Proyek X 2025) & Benchmark PT Pertamina (Persero) - Direktorat Manajemen Risiko / Permen BUMN No.02/2023
A5: 1. LIMA PILAR KESEHATAN PROYEK (PROJECT HEALTH) & FORMULA
A6: Pilar | B6: Indikator Utama | C6: Formula | D6: Bobot dalam PHS | E6: Sumber / Referensi
A7: Financial Health | B7: Cost Performance Index (CPI) Cost Variance (CV) | C7: CPI = EV / AC CV = EV - AC | D7: 20% | E7: Earned Value Management (EVM) - PMI Standard; ScheduleReader.com, 'Managing Project Health with SPI & CPI'
A8: Schedule Health | B8: Schedule Performance Index (SPI) Schedule Variance (SV) | C8: SPI = EV / PV SV = EV - PV | D8: 0.2 | E8: Earned Value Management (EVM) - PMI Standard; ScheduleReader.com
A9: Supply Readiness Index (SRI) | B9: 5 parameter tertimbang pasokan (supply chain) | C9: SRI = S (Wi x Si) | D9: 0.2 | E9: Risk Register Proyek X - Pengelompokan Tahapan Pekerjaan Proyek (2025)
A10: Project Execution Index (PEI) | B10: 4 parameter tertimbang pelaksanaan EPC | C10: PEI = S (Pj x Wj) | D10: 0.2 | E10: Risk Register Proyek X 2025; praktik EPC Progress-S-Curve industri
A11: Commercial Readiness Index (CRI) | B11: 5 parameter tertimbang kesiapan komersial | C11: CRI = S (Wk x Sk) | D11: 0.2 | E11: Risk Register Proyek X 2025
A13: Overall Project Health Score (PHS)
A14: PHS = (FinancialScore x 0,20) + (ScheduleScore x 0,20) + (SRI x 0,20) + (PEI x 0,20) + (CRI x 0,20)
A15: Catatan: FinancialScore & ScheduleScore dikonversi dari CPI/SPI. Jika indeks >= 1,00, skor = 100 (maksimal). Jika < 1,00, skor = indeks x 100.
A17: 2. PARAMETER & BOBOT SUPPLY READINESS INDEX (SRI)
A18: Parameter | B18: Bobot | C18: Deskripsi
A19: Salt Contract | B19: 0.25 | C19: Kepastian kontrak pasokan bahan baku garam industri jangka panjang dengan PT Garam maupun pemasok luar negeri.
A20: Salt Inventory | B20: 0.2 | C20: Kesiapan & kapasitas operasional gudang penyimpanan garam di pelabuhan dan lokasi pabrik.
A21: Supplier Qualification | B21: 0.2 | C21: Tingkat pemenuhan kualifikasi teknis dan standar kualitas garam dari para calon pemasok.
A22: Shipping Readiness | B22: 0.2 | C22: Kesiapan fasilitas pelabuhan, ketersediaan armada kapal logistik, dan jalur bongkar muat garam.
A23: Utility Readiness | B23: 0.15 | C23: Jaminan kesiapan tie-in pasokan gas bumi dari SKK Migas, air proses, uap panas, dan ketersediaan daya listrik.
A25: 3. PARAMETER & BOBOT PROJECT EXECUTION INDEX (PEI)
A26: Parameter | B26: Bobot | C26: Deskripsi
A27: Engineering Progress | B27: 0.25 | C27: Persentase penyelesaian gambar kerja detail (DED), dokumen spesifikasi teknis, dan persetujuan vendor drawings.
A28: Procurement Progress | B28: 0.3 | C28: Kemajuan pengadaan barang, khususnya long lead items (menara karbonasi, kiln dekomposisi, reaktor utama).
A29: Construction Progress | B29: 0.35 | C29: Kemajuan fisik konstruksi sipil, pondasi alat berat, struktur baja, instalasi mekanikal, kelistrikan, pemipaan.
A30: Commissioning Preparation | B30: 0.1 | C30: Penyelesaian dokumen prosedur pengujian, tim start-up, Loop Test instrumen, dan suku cadang awal operasional.
A32: 4. PARAMETER & BOBOT COMMERCIAL READINESS INDEX (CRI)
A33: Parameter | B33: Bobot | C33: Deskripsi
A34: Offtake Agreement | B34: 0.2 | C34: Jumlah volume produk yang telah terikat dalam nota kesepahaman (MOU/Offtake Agreement) dengan pembeli domestik.
A35: Marketing Strategy | B35: 0.2 | C35: Kesiapan strategi penetapan harga kompetitif terhadap produk impor dan diversifikasi varian produk.
A36: Distribution Readiness | B36: 0.15 | C36: Kesiapan logistik pengiriman produk akhir: bagging unit, armada pengangkutan darat, konveyor pelabuhan.
A37: Operation Team Ready | B37: 0.2 | C37: Kesiapan tim operasi pabrik: sertifikasi operator, SOP pengoperasian, pelatihan simulasi kondisi darurat.
A38: Product Qualification | B38: 0.25 | C38: Kesiapan laboratorium pengujian mutu produk & sertifikasi SNI agar memenuhi kualifikasi industri premium.
A40: 5. TABEL BATAS TOLERANSI (THRESHOLD) - SISTEM RAG (RED-AMBER-GREEN)
A41: Pilar Kesehatan | B41: Indikator | C41: Hijau | D41: Kuning | E41: Oranye | F41: Merah
A42: Financial Health | B42: CPI | C42: CPI >= 1,00 | D42: 0,95-0,99 | E42: 0,90-0,94 | F42: CPI < 0,90
A43: Schedule Health | B43: SPI | C43: SPI >= 1,00 | D43: 0,95-0,99 | E43: 0,90-0,94 | F43: SPI < 0,90
A44: Supply Readiness | B44: SRI | C44: SRI >= 90% | D44: 75-89% | E44: 65-74% | F44: SRI < 65%
A45: Project Execution | B45: Deviasi Fisik | C45: <= 4% | D45: 4,1-6% | E45: 6,1-10% | F45: > 10%
A46: Commercial Readiness | B46: CRI | C46: CRI >= 80% | D46: 60-79% | E46: 50-59% | F46: CRI < 50%
A47: Overall Health | B47: PHS | C47: 90-100% | D47: 75-89% | E47: 60-74% | F47: < 60%
...

Sheet Input_Bulanan
C2: INPUT DATA BULANAN — DIISI OLEH PIC / PROJECT CONTROL SETIAP PERIODE PELAPORAN
C3: Sel KUNING (font biru) = input manual. Sel ABU-ABU = formula otomatis, jangan diubah manual. Arahkan kursor ke label bertanda (i) untuk penjelasan parameter.
C4: Nama Perusahaan | D4: Perusahaan X | F4: Nama Proyek | G4: Proyek X
C5: Periode Pelaporan (Bulan/Tahun) | D5: Agustus 2026 | E5: Status Dokumen | F5: DRAFT
C7: 1. EARNED VALUE MANAGEMENT (EVM) — FINANCIAL & SCHEDULE HEALTH (satuan: USD Juta, kumulatif)
C8: Planned Value (PV) — kumulatif s.d. periode ini | D8: 100 | E8: NPV
C9: Earned Value (EV) — kumulatif s.d. periode ini | D9: 100
C10: Actual Cost (AC) — kumulatif s.d. periode ini | D10: 100
C11: Cost Performance Index (CPI = EV/AC) | D11: =D9/D10 -> 1
C12: Cost Variance (CV = EV-AC), USD Juta | D12: =D9-D10 -> 0
C13: Schedule Performance Index (SPI = EV/PV) | D13: =D9/D8 -> 1
C14: Schedule Variance (SV = EV-PV), USD Juta | D14: =D9-D8 -> 0
C16: 2. SUPPLY READINESS INDEX (SRI) — skor kesiapan tiap parameter
C17: Salt Contract (bobot 25%) | D17: 0.1
C18: Salt Inventory (bobot 20%) | D18: 0.05 | E18: Salt Readiness
C19: Supplier Qualification (bobot 20%) | D19: 0.04
C20: Shipping Readiness (bobot 20%) | D20: 0.06
C21: Utility Readiness (bobot 15%) | D21: 0.08
C22: SRI — Supply Readiness Index (tertimbang) | D22: =(D17*0.25+D18*0.2+D19*0.2+D20*0.2+D21*0.15) -> 0.067
C24: 3. PROJECT EXECUTION INDEX (PEI) — progres aktual tiap parameter
C25: Engineering Progress (bobot 25%) | D25: 0.88 | F25: Planned Value (PV) — kumulatif s.d. periode ini
C26: Procurement Progress (bobot 30%) | D26: 0.73 | F26: Earned Value (EV) — kumulatif s.d. periode ini
C27: Construction Progress (bobot 35%) | D27: 0.82 | F27: Actual Cost (AC) — kumulatif s.d. periode ini
C28: Commissioning Preparation (bobot 10%) | D28: 0.42 | E28: Pencapaian Performace Test (Kaitannya dengan quality) | F28: Cost Performance Index (CPI = EV/AC)
C29: PEI — Project Execution Index (tertimbang) | D29: =(D25*0.25+D26*0.3+D27*0.35+D28*0.1) -> 0.768 | F29: Cost Variance (CV = EV-AC), USD Juta
C30: Deviasi Kemajuan Fisik vs Target (S-Curve) | D30: 0.058 | F30: Schedule Performance Index (SPI = EV/PV)
F31: Schedule Variance (SV = EV-PV), USD Juta
C32: 4. COMMERCIAL READINESS INDEX (CRI) — skor kesiapan tiap parameter
C33: Offtake Agreement (bobot 20%) | D33: 0.6
C34: Marketing Strategy (bobot 20%) | D34: 0.6
C35: Distribution Readiness (bobot 15%) | D35: 0.8
C36: Operation Team Ready (bobot 20%) | D36: 0.8
C37: Product Qualification (bobot 25%) | D37: 0.4 | E37: Izin Edar | F37: Regulatory Readiness
C38: CRI — Commercial Readiness Index (tertimbang) | D38: =(D33*0.2+D34*0.2+D35*0.15+D36*0.2+D37*0.25) -> 0.62
C40: 5. OVERALL RISK INDEX — sub-indeks risiko (skor 0-100, benchmark Pertamina)
C41: Supply Risk Index (bobot 40%) | D41: =D22*100 -> 6.7
C42: Execution Risk Index (bobot 40%) | D42: =D29*100 -> 76.8
C43: Commercial Risk Index (bobot 20%) | D43: =D38*100 -> 62
C44: Overall Risk Index (tertimbang, skala 0-100) | D44: =(D41*0.4)+(D42*0.4)+(D43*0.2) -> 45.8
C45: Overall Risk Level (5 Tingkat, formula) | D45: =IF(D44<=20,"Low",IF(D44<=44,"Low to Moderate",IF(D44<=60,"Moderate",IF(D44<=76,"Moderate to High","High")))) -> Moderate
...

Sheet Risk_Action_Tracker
B2: EXECUTIVE ACTION TRACKER — DIREKSI / PROJECT STEERING COMMITTEE (PSC)
B3: Proyek X Project Perusahaan X — diperbarui setiap periode pelaporan bulanan. Kategori Level mengikuti klasifikasi 5-tingkat Pedoman Manajemen Risiko Perusahaan X.
B5: No | C5: Isu Strategis / Peristiwa Risiko Kritis | D5: Kategori & Level Risiko | E5: Keputusan & Rencana Tindakan Diperlukan | F5: PIC (Unit Penanggung Jawab) | G5: Perkiraan Dampak Finansial & Kelayakan NPV | Z5: Helper Priority Score
B6: 1 | C6: Ketergantungan Antarmuka (Interface) Lintas EPC-A, B, C, D | D6: Eksekusi — High | E6: Mengesahkan pembentukan tim Interface Coordinator dan menerapkan Interface Management Plan (IMP) yang mengikat seluruh kontraktor; mengharuskan Rekind menyelaraskan jadwal penyusunan gambar detail dengan kemajuan ISBL EPC-A. | F6: VP Proyek Proyek X & SVP Pengembangan Portofolio | G6: Mencegah kegagalan penyelesaian proyek bersamaan, mengamankan target COD Maret 2028, melindungi NPV sebesar USD 77,60 Juta. | Z6: =IF(D6="","", IF(ISNUMBER(SEARCH("Moderate to High", D6)), 40, IF(ISNUMBER(SEARCH("High", D6)), 50, IF(ISNUMBER(SEARCH("Low to Moderate", D6)), 20, IF(ISNUMBER(SEARCH("Moderate", D6)), 30, 10)))) + (1/ROW())) -> 50.166667
B7: 2 | C7: Keterbatasan Kapasitas Keuangan Rekind (EPC-B) | D7: Finansial — Moderate to High | E7: Memberikan dispensasi perpanjangan jaminan pelaksanaan secara terkendali; meminta Parent Company Guarantee dari PT Perusahaan Induk X (Persero) untuk menjamin ketersediaan pendanaan bila Rekind menghadapi kendala likuiditas. | F7: Direktur Utama Perusahaan X & SVP Keuangan | G7: Melindungi penyelesaian gardu kelistrikan dan fasilitas tie-in, menghindari denda klaim tambahan dari EPC-A. | Z7: =IF(D7="","", IF(ISNUMBER(SEARCH("Moderate to High", D7)), 40, IF(ISNUMBER(SEARCH("High", D7)), 50, IF(ISNUMBER(SEARCH("Low to Moderate", D7)), 20, IF(ISNUMBER(SEARCH("Moderate", D7)), 30, 10)))) + (1/ROW())) -> 40.142857
B8: 3 | C8: Kelangkaan & Hambatan Perizinan Impor Garam Industri | D8: Hulu / Supply — Moderate to High | E8: Lobi aktif dan koordinasi dengan Kementerian Perindustrian serta Kementerian Kelautan dan Perikanan guna mengamankan alokasi kuota impor tahunan setahun sebelum operasional dimulai, merujuk Perpres No.17/2025. | F8: Direktur Utama Perusahaan X & SVP Pengembangan Portofolio | G8: Menghindari penghentian operasional akibat kekosongan bahan baku; menghemat potensi kerugian EBITDA Rp 137 Miliar/kuartal. | Z8: =IF(D8="","", IF(ISNUMBER(SEARCH("Moderate to High", D8)), 40, IF(ISNUMBER(SEARCH("High", D8)), 50, IF(ISNUMBER(SEARCH("Low to Moderate", D8)), 20, IF(ISNUMBER(SEARCH("Moderate", D8)), 30, 10)))) + (1/ROW())) -> 40.125
B9: 4 | C9: Fluktuasi Nilai Tukar Valas Terhadap Sisa Pembayaran Kontrak EPC-A | D9: Keuangan — Moderate | E9: Menginstruksikan Kompartemen Keuangan mengimplementasikan strategi hedging valas (forward/opsi) bekerja sama dengan bank BUMN nasional untuk mengunci porsi sisa pembayaran dalam USD. | F9: Direktur Keuangan Perusahaan X | G9: Mengeliminasi risiko pembengkakan biaya investasi riil akibat depresiasi rupiah; mengamankan ambang batas investasi USD 297,67 Juta. | Z9: =IF(D9="","", IF(ISNUMBER(SEARCH("Moderate to High", D9)), 40, IF(ISNUMBER(SEARCH("High", D9)), 50, IF(ISNUMBER(SEARCH("Low to Moderate", D9)), 20, IF(ISNUMBER(SEARCH("Moderate", D9)), 30, 10)))) + (1/ROW())) -> 30.111111
B10: 5 | C10: Hambatan Penerbitan PBG & SLF di Lahan Tursina Barat | D10: Regulasi — Moderate | E10: Membentuk tim percepatan perizinan internal untuk koordinasi harian dengan DLH Kota X dan Dinas PUPR Provinsi Provinsi X guna mempercepat adendum dokumen lingkungan di lahan sengketa. | F10: VP Hukum & Humas Perusahaan X | G10: Mencegah keterlambatan masa efektif konstruksi fisik; menghemat opportunity cost of capital senilai Rp 500 Juta/bulan. | Z10: =IF(D10="","", IF(ISNUMBER(SEARCH("Moderate to High", D10)), 40, IF(ISNUMBER(SEARCH("High", D10)), 50, IF(ISNUMBER(SEARCH("Low to Moderate", D10)), 20, IF(ISNUMBER(SEARCH("Moderate", D10)), 30, 10)))) + (1/ROW())) -> 30.1
Z11: =IF(D11="","", IF(ISNUMBER(SEARCH("Moderate to High", D11)), 40, IF(ISNUMBER(SEARCH("High", D11)), 50, IF(ISNUMBER(SEARCH("Low to Moderate", D11)), 20, IF(ISNUMBER(SEARCH("Moderate", D11)), 30, 10)))) + (1/ROW()))
B12: Sumber tata kelola: Risk Register Proyek X 2025; kerangka Gate Review & FID PT Pertamina (Persero); Weighted Project Top Risk (Financial Materiality 40%, Strategic Impact 30%, Life Cycle Phase 15%, Financial Health Impact 10%, Baseline Risk Complexity 5%). Level risiko mengikuti klasifikasi 5-tingkat Pedoman Manajemen Risiko Perusahaan X: Low / Low to Moderate / Moderate / Moderate to High / High. | Z12: =IF(D12="","", IF(ISNUMBER(SEARCH("Moderate to High", D12)), 40, IF(ISNUMBER(SEARCH("High", D12)), 50, IF(ISNUMBER(SEARCH("Low to Moderate", D12)), 20, IF(ISNUMBER(SEARCH("Moderate", D12)), 30, 10)))) + (1/ROW()))
Z13: =IF(D13="","", IF(ISNUMBER(SEARCH("Moderate to High", D13)), 40, IF(ISNUMBER(SEARCH("High", D13)), 50, IF(ISNUMBER(SEARCH("Low to Moderate", D13)), 20, IF(ISNUMBER(SEARCH("Moderate", D13)), 30, 10)))) + (1/ROW()))
Z14: =IF(D14="","", IF(ISNUMBER(SEARCH("Moderate to High", D14)), 40, IF(ISNUMBER(SEARCH("High", D14)), 50, IF(ISNUMBER(SEARCH("Low to Moderate", D14)), 20, IF(ISNUMBER(SEARCH("Moderate", D14)), 30, 10)))) + (1/ROW()))
Z15: =IF(D15="","", IF(ISNUMBER(SEARCH("Moderate to High", D15)), 40, IF(ISNUMBER(SEARCH("High", D15)), 50, IF(ISNUMBER(SEARCH("Low to Moderate", D15)), 20, IF(ISNUMBER(SEARCH("Moderate", D15)), 30, 10)))) + (1/ROW()))
B16: DINAMIKA PERGERAKAN RISIKO (BULAN BERJALAN)
B17: Risiko Baru (New Risk) | C17: =Input_Bulanan!F56 -> 2 | D17: Perubahan tarif pajak masukan impor garam industri; risiko sengketa lahan tambahan di area laydown.
B18: Risiko Eskalasi (Escalated Risk) | C18: =Input_Bulanan!F57 -> 3 | D18: Peningkatan level risiko keterlambatan Rekind akibat kendala arus kas internal.
B19: Risiko Menurun (Reduced Risk) | C19: =Input_Bulanan!F58 -> 5 | D19: Penurunan risiko dampak sosial setelah disepakatinya kuota tenaga kerja lokal.
B20: Risiko Ditutup (Closed Risk) | C20: =Input_Bulanan!F59 -> 4 | D20: Penutupan risiko kelayakan AMDAL seiring diterbitkannya izin adendum lingkungan DLH Bontang.
B22: TOP RISK REGISTER (C1-C4) - DETAIL LIKELIHOOD x CONSEQUENCE
B23: Kode | C23: Deskripsi Risiko | D23: Kategori | E23: L | F23: C | G23: Score / Level
B24: =Input_Bulanan!C74 -> C1 | C24: =Input_Bulanan!D74 -> Salt Supply Disruption (gangguan pasokan garam industri) | D24: =Input_Bulanan!E74 -> Hulu / Supply | E24: =Input_Bulanan!F74 -> 4 | F24: =Input_Bulanan!G74 -> 5 | G24: =Input_Bulanan!H74 & " | " & Input_Bulanan!I74 -> 24 | High
B25: =Input_Bulanan!C75 -> C2 | C25: =Input_Bulanan!D75 -> Commissioning Delay (keterlambatan commissioning) | D25: =Input_Bulanan!E75 -> Eksekusi | E25: =Input_Bulanan!F75 -> 5 | F25: =Input_Bulanan!G75 -> 5 | G25: =Input_Bulanan!H75 & " | " & Input_Bulanan!I75 -> 25 | High
B26: =Input_Bulanan!C76 -> C3 | C26: =Input_Bulanan!D76 -> EPC Interface Issue (isu EPC interface lintas kontraktor) | D26: =Input_Bulanan!E76 -> Eksekusi | E26: =Input_Bulanan!F76 -> 4 | F26: =Input_Bulanan!G76 -> 4 | G26: =Input_Bulanan!H76 & " | " & Input_Bulanan!I76 -> 19 | Moderate to High
B27: =Input_Bulanan!C77 -> C4 | C27: =Input_Bulanan!D77 -> Long Lead Equipment (keterlambatan peralatan utama) | D27: =Input_Bulanan!E77 -> Pengadaan | E27: =Input_Bulanan!F77 -> 3 | F27: =Input_Bulanan!G77 -> 3 | G27: =Input_Bulanan!H77 & " | " & Input_Bulanan!I77 -> 13 | Moderate
